Assignment1 - C++/grader/tests/intermediate-exec-cancel-race.in

    # Adds a pair of matchable concurrent orders, cancels them immediately
    # So the exec may or may not happen depending on if the cancels happen first
    
2
o
0 B 0 GOOG 2700 1
0 C 0
1 S 1 GOOG 2700 1
1 C 1
0 w 1
1 w 0
0 B 2 GOOG 2700 1
0 C 2
1 S 3 GOOG 2700 1
1 C 3
0 w 3
1 w 2
0 B 4 GOOG 2700 1
0 C 4
1 S 5 GOOG 2700 1
1 C 5
0 w 5
1 w 4
0 B 6 GOOG 2700 1
0 C 6
1 S 7 GOOG 2700 1
1 C 7
0 w 7
1 w 6
0 B 8 GOOG 2700 1
0 C 8
1 S 9 GOOG 2700 1
1 C 9
0 w 9
1 w 8
0 B 10 GOOG 2700 1
0 C 10
1 S 11 GOOG 2700 1
1 C 11
0 w 11
1 w 10
0 B 12 GOOG 2700 1
0 C 12
1 S 13 GOOG 2700 1
1 C 13
0 w 13
1 w 12
0 B 14 GOOG 2700 1
0 C 14
1 S 15 GOOG 2700 1
1 C 15
0 w 15
1 w 14
0 B 16 GOOG 2700 1
0 C 16
1 S 17 GOOG 2700 1
1 C 17
0 w 17
1 w 16
0 B 18 GOOG 2700 1
0 C 18
1 S 19 GOOG 2700 1
1 C 19
0 w 19
1 w 18
0 B 20 GOOG 2700 1
0 C 20
1 S 21 GOOG 2700 1
1 C 21
0 w 21
1 w 20
0 B 22 GOOG 2700 1
0 C 22
1 S 23 GOOG 2700 1
1 C 23
0 w 23
1 w 22
0 B 24 GOOG 2700 1
0 C 24
1 S 25 GOOG 2700 1
1 C 25
0 w 25
1 w 24
0 B 26 GOOG 2700 1
0 C 26
1 S 27 GOOG 2700 1
1 C 27
0 w 27
1 w 26
0 B 28 GOOG 2700 1
0 C 28
1 S 29 GOOG 2700 1
1 C 29
0 w 29
1 w 28
0 B 30 GOOG 2700 1
0 C 30
1 S 31 GOOG 2700 1
1 C 31
0 w 31
1 w 30
0 B 32 GOOG 2700 1
0 C 32
1 S 33 GOOG 2700 1
1 C 33
0 w 33
1 w 32
0 B 34 GOOG 2700 1
0 C 34
1 S 35 GOOG 2700 1
1 C 35
0 w 35
1 w 34
0 B 36 GOOG 2700 1
0 C 36
1 S 37 GOOG 2700 1
1 C 37
0 w 37
1 w 36
0 B 38 GOOG 2700 1
0 C 38
1 S 39 GOOG 2700 1
1 C 39
0 w 39
1 w 38
0 B 40 GOOG 2700 1
0 C 40
1 S 41 GOOG 2700 1
1 C 41
0 w 41
1 w 40
0 B 42 GOOG 2700 1
0 C 42
1 S 43 GOOG 2700 1
1 C 43
0 w 43
1 w 42
0 B 44 GOOG 2700 1
0 C 44
1 S 45 GOOG 2700 1
1 C 45
0 w 45
1 w 44
0 B 46 GOOG 2700 1
0 C 46
1 S 47 GOOG 2700 1
1 C 47
0 w 47
1 w 46
0 B 48 GOOG 2700 1
0 C 48
1 S 49 GOOG 2700 1
1 C 49
0 w 49
1 w 48
0 B 50 GOOG 2700 1
0 C 50
1 S 51 GOOG 2700 1
1 C 51
0 w 51
1 w 50
0 B 52 GOOG 2700 1
0 C 52
1 S 53 GOOG 2700 1
1 C 53
0 w 53
1 w 52
0 B 54 GOOG 2700 1
0 C 54
1 S 55 GOOG 2700 1
1 C 55
0 w 55
1 w 54
0 B 56 GOOG 2700 1
0 C 56
1 S 57 GOOG 2700 1
1 C 57
0 w 57
1 w 56
0 B 58 GOOG 2700 1
0 C 58
1 S 59 GOOG 2700 1
1 C 59
0 w 59
1 w 58
0 B 60 GOOG 2700 1
0 C 60
1 S 61 GOOG 2700 1
1 C 61
0 w 61
1 w 60
0 B 62 GOOG 2700 1
0 C 62
1 S 63 GOOG 2700 1
1 C 63
0 w 63
1 w 62
0 B 64 GOOG 2700 1
0 C 64
1 S 65 GOOG 2700 1
1 C 65
0 w 65
1 w 64
0 B 66 GOOG 2700 1
0 C 66
1 S 67 GOOG 2700 1
1 C 67
0 w 67
1 w 66
0 B 68 GOOG 2700 1
0 C 68
1 S 69 GOOG 2700 1
1 C 69
0 w 69
1 w 68
0 B 70 GOOG 2700 1
0 C 70
1 S 71 GOOG 2700 1
1 C 71
0 w 71
1 w 70
0 B 72 GOOG 2700 1
0 C 72
1 S 73 GOOG 2700 1
1 C 73
0 w 73
1 w 72
0 B 74 GOOG 2700 1
0 C 74
1 S 75 GOOG 2700 1
1 C 75
0 w 75
1 w 74
0 B 76 GOOG 2700 1
0 C 76
1 S 77 GOOG 2700 1
1 C 77
0 w 77
1 w 76
0 B 78 GOOG 2700 1
0 C 78
1 S 79 GOOG 2700 1
1 C 79
0 w 79
1 w 78
0 B 80 GOOG 2700 1
0 C 80
1 S 81 GOOG 2700 1
1 C 81
0 w 81
1 w 80
0 B 82 GOOG 2700 1
0 C 82
1 S 83 GOOG 2700 1
1 C 83
0 w 83
1 w 82
0 B 84 GOOG 2700 1
0 C 84
1 S 85 GOOG 2700 1
1 C 85
0 w 85
1 w 84
0 B 86 GOOG 2700 1
0 C 86
1 S 87 GOOG 2700 1
1 C 87
0 w 87
1 w 86
0 B 88 GOOG 2700 1
0 C 88
1 S 89 GOOG 2700 1
1 C 89
0 w 89
1 w 88
0 B 90 GOOG 2700 1
0 C 90
1 S 91 GOOG 2700 1
1 C 91
0 w 91
1 w 90
0 B 92 GOOG 2700 1
0 C 92
1 S 93 GOOG 2700 1
1 C 93
0 w 93
1 w 92
0 B 94 GOOG 2700 1
0 C 94
1 S 95 GOOG 2700 1
1 C 95
0 w 95
1 w 94
0 B 96 GOOG 2700 1
0 C 96
1 S 97 GOOG 2700 1
1 C 97
0 w 97
1 w 96
0 B 98 GOOG 2700 1
0 C 98
1 S 99 GOOG 2700 1
1 C 99
0 w 99
1 w 98
0 B 100 GOOG 2700 1
0 C 100
1 S 101 GOOG 2700 1
1 C 101
0 w 101
1 w 100
0 B 102 GOOG 2700 1
0 C 102
1 S 103 GOOG 2700 1
1 C 103
0 w 103
1 w 102
0 B 104 GOOG 2700 1
0 C 104
1 S 105 GOOG 2700 1
1 C 105
0 w 105
1 w 104
0 B 106 GOOG 2700 1
0 C 106
1 S 107 GOOG 2700 1
1 C 107
0 w 107
1 w 106
0 B 108 GOOG 2700 1
0 C 108
1 S 109 GOOG 2700 1
1 C 109
0 w 109
1 w 108
0 B 110 GOOG 2700 1
0 C 110
1 S 111 GOOG 2700 1
1 C 111
0 w 111
1 w 110
0 B 112 GOOG 2700 1
0 C 112
1 S 113 GOOG 2700 1
1 C 113
0 w 113
1 w 112
0 B 114 GOOG 2700 1
0 C 114
1 S 115 GOOG 2700 1
1 C 115
0 w 115
1 w 114
0 B 116 GOOG 2700 1
0 C 116
1 S 117 GOOG 2700 1
1 C 117
0 w 117
1 w 116
0 B 118 GOOG 2700 1
0 C 118
1 S 119 GOOG 2700 1
1 C 119
0 w 119
1 w 118
0 B 120 GOOG 2700 1
0 C 120
1 S 121 GOOG 2700 1
1 C 121
0 w 121
1 w 120
0 B 122 GOOG 2700 1
0 C 122
1 S 123 GOOG 2700 1
1 C 123
0 w 123
1 w 122
0 B 124 GOOG 2700 1
0 C 124
1 S 125 GOOG 2700 1
1 C 125
0 w 125
1 w 124
0 B 126 GOOG 2700 1
0 C 126
1 S 127 GOOG 2700 1
1 C 127
0 w 127
1 w 126
0 B 128 GOOG 2700 1
0 C 128
1 S 129 GOOG 2700 1
1 C 129
0 w 129
1 w 128
0 B 130 GOOG 2700 1
0 C 130
1 S 131 GOOG 2700 1
1 C 131
0 w 131
1 w 130
0 B 132 GOOG 2700 1
0 C 132
1 S 133 GOOG 2700 1
1 C 133
0 w 133
1 w 132
0 B 134 GOOG 2700 1
0 C 134
1 S 135 GOOG 2700 1
1 C 135
0 w 135
1 w 134
0 B 136 GOOG 2700 1
0 C 136
1 S 137 GOOG 2700 1
1 C 137
0 w 137
1 w 136
0 B 138 GOOG 2700 1
0 C 138
1 S 139 GOOG 2700 1
1 C 139
0 w 139
1 w 138
0 B 140 GOOG 2700 1
0 C 140
1 S 141 GOOG 2700 1
1 C 141
0 w 141
1 w 140
0 B 142 GOOG 2700 1
0 C 142
1 S 143 GOOG 2700 1
1 C 143
0 w 143
1 w 142
0 B 144 GOOG 2700 1
0 C 144
1 S 145 GOOG 2700 1
1 C 145
0 w 145
1 w 144
0 B 146 GOOG 2700 1
0 C 146
1 S 147 GOOG 2700 1
1 C 147
0 w 147
1 w 146
0 B 148 GOOG 2700 1
0 C 148
1 S 149 GOOG 2700 1
1 C 149
0 w 149
1 w 148
0 B 150 GOOG 2700 1
0 C 150
1 S 151 GOOG 2700 1
1 C 151
0 w 151
1 w 150
0 B 152 GOOG 2700 1
0 C 152
1 S 153 GOOG 2700 1
1 C 153
0 w 153
1 w 152
0 B 154 GOOG 2700 1
0 C 154
1 S 155 GOOG 2700 1
1 C 155
0 w 155
1 w 154
0 B 156 GOOG 2700 1
0 C 156
1 S 157 GOOG 2700 1
1 C 157
0 w 157
1 w 156
0 B 158 GOOG 2700 1
0 C 158
1 S 159 GOOG 2700 1
1 C 159
0 w 159
1 w 158
0 B 160 GOOG 2700 1
0 C 160
1 S 161 GOOG 2700 1
1 C 161
0 w 161
1 w 160
0 B 162 GOOG 2700 1
0 C 162
1 S 163 GOOG 2700 1
1 C 163
0 w 163
1 w 162
0 B 164 GOOG 2700 1
0 C 164
1 S 165 GOOG 2700 1
1 C 165
0 w 165
1 w 164
0 B 166 GOOG 2700 1
0 C 166
1 S 167 GOOG 2700 1
1 C 167
0 w 167
1 w 166
0 B 168 GOOG 2700 1
0 C 168
1 S 169 GOOG 2700 1
1 C 169
0 w 169
1 w 168
0 B 170 GOOG 2700 1
0 C 170
1 S 171 GOOG 2700 1
1 C 171
0 w 171
1 w 170
0 B 172 GOOG 2700 1
0 C 172
1 S 173 GOOG 2700 1
1 C 173
0 w 173
1 w 172
0 B 174 GOOG 2700 1
0 C 174
1 S 175 GOOG 2700 1
1 C 175
0 w 175
1 w 174
0 B 176 GOOG 2700 1
0 C 176
1 S 177 GOOG 2700 1
1 C 177
0 w 177
1 w 176
0 B 178 GOOG 2700 1
0 C 178
1 S 179 GOOG 2700 1
1 C 179
0 w 179
1 w 178
0 B 180 GOOG 2700 1
0 C 180
1 S 181 GOOG 2700 1
1 C 181
0 w 181
1 w 180
0 B 182 GOOG 2700 1
0 C 182
1 S 183 GOOG 2700 1
1 C 183
0 w 183
1 w 182
0 B 184 GOOG 2700 1
0 C 184
1 S 185 GOOG 2700 1
1 C 185
0 w 185
1 w 184
0 B 186 GOOG 2700 1
0 C 186
1 S 187 GOOG 2700 1
1 C 187
0 w 187
1 w 186
0 B 188 GOOG 2700 1
0 C 188
1 S 189 GOOG 2700 1
1 C 189
0 w 189
1 w 188
0 B 190 GOOG 2700 1
0 C 190
1 S 191 GOOG 2700 1
1 C 191
0 w 191
1 w 190
0 B 192 GOOG 2700 1
0 C 192
1 S 193 GOOG 2700 1
1 C 193
0 w 193
1 w 192
0 B 194 GOOG 2700 1
0 C 194
1 S 195 GOOG 2700 1
1 C 195
0 w 195
1 w 194
0 B 196 GOOG 2700 1
0 C 196
1 S 197 GOOG 2700 1
1 C 197
0 w 197
1 w 196
0 B 198 GOOG 2700 1
0 C 198
1 S 199 GOOG 2700 1
1 C 199
0 w 199
1 w 198
0 B 200 GOOG 2700 1
0 C 200
1 S 201 GOOG 2700 1
1 C 201
0 w 201
1 w 200
0 B 202 GOOG 2700 1
0 C 202
1 S 203 GOOG 2700 1
1 C 203
0 w 203
1 w 202
0 B 204 GOOG 2700 1
0 C 204
1 S 205 GOOG 2700 1
1 C 205
0 w 205
1 w 204
0 B 206 GOOG 2700 1
0 C 206
1 S 207 GOOG 2700 1
1 C 207
0 w 207
1 w 206
0 B 208 GOOG 2700 1
0 C 208
1 S 209 GOOG 2700 1
1 C 209
0 w 209
1 w 208
0 B 210 GOOG 2700 1
0 C 210
1 S 211 GOOG 2700 1
1 C 211
0 w 211
1 w 210
0 B 212 GOOG 2700 1
0 C 212
1 S 213 GOOG 2700 1
1 C 213
0 w 213
1 w 212
0 B 214 GOOG 2700 1
0 C 214
1 S 215 GOOG 2700 1
1 C 215
0 w 215
1 w 214
0 B 216 GOOG 2700 1
0 C 216
1 S 217 GOOG 2700 1
1 C 217
0 w 217
1 w 216
0 B 218 GOOG 2700 1
0 C 218
1 S 219 GOOG 2700 1
1 C 219
0 w 219
1 w 218
0 B 220 GOOG 2700 1
0 C 220
1 S 221 GOOG 2700 1
1 C 221
0 w 221
1 w 220
0 B 222 GOOG 2700 1
0 C 222
1 S 223 GOOG 2700 1
1 C 223
0 w 223
1 w 222
0 B 224 GOOG 2700 1
0 C 224
1 S 225 GOOG 2700 1
1 C 225
0 w 225
1 w 224
0 B 226 GOOG 2700 1
0 C 226
1 S 227 GOOG 2700 1
