Assignment1 - C++/test/input1.txt
B 101 TSLA 2800 15
B 102 TSLA 2800 10
B 103 TSLA 2800 10 
B 104 TSLA 2800 10 
B 105 TSLA 2800 15 

B 110 TSLA 2700 15
B 111 TSLA 2700 10
B 112 TSLA 2700 10 
B 113 TSLA 2700 10 
B 114 TSLA 2700 15
C 101
C 102
C 103
C 104
C 105
C 110
C 111
C 112
C 113
C 114
