Assignment1 - C++/test/input2.txt
B 100 TSLA 2700 15 
B 101 TSLA 2750 20
S 102 TSLA 2600 40 
B 103 TSLA 2700 5 
S 104 TSLA 2500 15
S 105 TSLA 2600 10
S 106 TSLA 2650 10
B 107 TSLA 3000 35 
C 107
C 100
C 101
C 102
C 103
C 104
C 105
C 106 
C 107
C 108
C 109
C 110
