Assignment1 - C++/test/input-test.txt
C 0
C 1
B 0 GOOG 2727 63
C 2
C 2
B 1 APPL 2732 56
B 2 APPL 2780 7
B 3 APPL 2730 36
C 7
B 4 AMZN 2760 87
C 9
C 10
B 5 APPL 2721 94
S 6 GOOG 2785 44
B 7 MFST 2768 66
S 8 GOOG 2737 79
B 9 FB 2780 98
S 10 MFST 2782 50
B 11 MFST 2795 54
B 12 FB 2748 72
